[<tr class="Error" valign="top">
<td>.setUpClass (scripts.hbf.test_hbs_fw.TestNetworkPolicy)</td><td>Failure</td><td><span onclick="javascript:toggleErrorDetail(this)" style="cursor:pointer">Details</span><code style="display:none">
<br/>
<br/>Traceback (most recent call last):<br/>testtools.testresult.real._StringException: Traceback (most recent call last):<br/>  File "/contrail-test/scripts/hbf/test_hbs_fw.py", line 37, in setUpClass<br/>    cls.hbs.setUp()<br/>  File "/contrail-test/fixtures/k8s/hbs.py", line 63, in setUp<br/>    self.create_hbs_ds()<br/>  File "/contrail-test/fixtures/k8s/hbs.py", line 261, in create_hbs_ds<br/>    assert ds.verify_on_setup()<br/>AssertionError<br/>
<br/>
</code></td><td>0.000</td><td><a href="">
		    Log File
		  </a></td>
</tr>, <tr class="Error" valign="top">
<td>TestFabricFWD.test_deployment_with_replica_update_for_fabric_fwd[k8s_sanity]</td><td>Failure</td><td><span onclick="javascript:toggleErrorDetail(this)" style="cursor:pointer">Details</span><code style="display:none">
<br/>
<br/>Traceback (most recent call last):<br/>testtools.testresult.real._StringException: Traceback (most recent call last):<br/>  File "/contrail-test/tcutils/wrappers.py", line 179, in wrapper<br/>    raise TestFailed("\n ".join(errmsg))<br/>tcutils.cores.TestFailed: Test failed: AssertionError<br/>Python 3.6.8: /usr/bin/python3<br/>Mon Aug 17 13:53:17 2020<br/>
<br/>A problem occurred in a Python script.  Here is the sequence of<br/>function calls leading up to the error, in the order they occurred.<br/>
<br/> /contrail-test/tcutils/wrappers.py in wrapper(self=&lt;scripts.k8s_scripts.test_fabric_forwarding.Test...ate_for_fabric_fwd[k8s_sanity] id=0x7f38bd540c88&gt;, *args=(), **kwargs={})<br/>   80             log.info('Initial checks done. Running the testcase now')<br/>   81             log.info('')<br/>   82             result = function(self, *args, **kwargs)<br/>   83             if self.inputs.upgrade:<br/>   84                 pid = os.getpid()<br/>result = None<br/>function = &lt;function TestFabricFWD.test_deployment_with_replica_update_for_fabric_fwd&gt;<br/>self = &lt;scripts.k8s_scripts.test_fabric_forwarding.Test...ate_for_fabric_fwd[k8s_sanity] id=0x7f38bd540c88&gt;<br/>args = ()<br/>kwargs = {}<br/>
<br/> /contrail-test/scripts/k8s_scripts/test_fabric_forwarding.py in test_deployment_with_replica_update_for_fabric_fwd(self=&lt;scripts.k8s_scripts.test_fabric_forwarding.Test...ate_for_fabric_fwd[k8s_sanity] id=0x7f38bd540c88&gt;)<br/>  221         dep_1 =  self.setup_deployment(name=name, namespace=namespace1_name,<br/>  222                                      metadata=metadata, spec=spec)<br/>  223         assert dep_1.verify_on_setup()<br/>  224         s_pod_fixtures = []<br/>  225         server_pods = dep_1.get_pods_list()<br/>dep_1 = &lt;k8s.deployment.DeploymentFixture object&gt;<br/>dep_1.verify_on_setup = &lt;bound method DeploymentFixture.verify_on_setup of &lt;k8s.deployment.DeploymentFixture object&gt;&gt;<br/>AssertionError: <br/>    __cause__ = None<br/>    __class__ = &lt;class 'AssertionError'&gt;<br/>    __context__ = None<br/>    __delattr__ = &lt;method-wrapper '__delattr__' of AssertionError object&gt;<br/>    __dict__ = {}<br/>    __dir__ = &lt;built-in method __dir__ of AssertionError object&gt;<br/>    __doc__ = 'Assertion failed.'<br/>    __eq__ = &lt;method-wrapper '__eq__' of AssertionError object&gt;<br/>    __format__ = &lt;built-in method __format__ of AssertionError object&gt;<br/>    __ge__ = &lt;method-wrapper '__ge__' of AssertionError object&gt;<br/>    __getattribute__ = &lt;method-wrapper '__getattribute__' of AssertionError object&gt;<br/>    __gt__ = &lt;method-wrapper '__gt__' of AssertionError object&gt;<br/>    __hash__ = &lt;method-wrapper '__hash__' of AssertionError object&gt;<br/>    __init__ = &lt;method-wrapper '__init__' of AssertionError object&gt;<br/>    __init_subclass__ = &lt;built-in method __init_subclass__ of type object&gt;<br/>    __le__ = &lt;method-wrapper '__le__' of AssertionError object&gt;<br/>    __lt__ = &lt;method-wrapper '__lt__' of AssertionError object&gt;<br/>    __ne__ = &lt;method-wrapper '__ne__' of AssertionError object&gt;<br/>    __new__ = &lt;built-in method __new__ of type object&gt;<br/>    __reduce__ = &lt;built-in method __reduce__ of AssertionError object&gt;<br/>    __reduce_ex__ = &lt;built-in method __reduce_ex__ of AssertionError object&gt;<br/>    __repr__ = &lt;method-wrapper '__repr__' of AssertionError object&gt;<br/>    __setattr__ = &lt;method-wrapper '__setattr__' of AssertionError object&gt;<br/>    __setstate__ = &lt;built-in method __setstate__ of AssertionError object&gt;<br/>    __sizeof__ = &lt;built-in method __sizeof__ of AssertionError object&gt;<br/>    __str__ = &lt;method-wrapper '__str__' of AssertionError object&gt;<br/>    __subclasshook__ = &lt;built-in method __subclasshook__ of type object&gt;<br/>    __suppress_context__ = False<br/>    __traceback__ = &lt;traceback object&gt;<br/>    args = ()<br/>    with_traceback = &lt;built-in method with_traceback of AssertionError object&gt;<br/>
<br/>The above is a description of an error in a Python program.  Here is<br/>the original traceback:<br/>
<br/>Traceback (most recent call last):<br/>  File "/contrail-test/tcutils/wrappers.py", line 82, in wrapper<br/>    result = function(self, *args, **kwargs)<br/>  File "/contrail-test/scripts/k8s_scripts/test_fabric_forwarding.py", line 223, in test_deployment_with_replica_update_for_fabric_fwd<br/>    assert dep_1.verify_on_setup()<br/>AssertionError<br/>
<br/>
</code></td><td>324.390</td><td><a href="http://10.204.216.50/Docs/logs/2008-55_2020_08_17_13_45_33/logs//testfabricfwd.html#test_deployment_with_replica_update_for_fabric_fwd">
		    Log File
		  </a></td>
</tr>, <tr class="Error" valign="top">
<td>TestNetworkPolicy.test_egress_rules_label_edit[k8s_sanity]</td><td>Failure</td><td><span onclick="javascript:toggleErrorDetail(this)" style="cursor:pointer">Details</span><code style="display:none">
<br/>
<br/>Traceback (most recent call last):<br/>testtools.testresult.real._StringException: Traceback (most recent call last):<br/>  File "/contrail-test/scripts/k8s_scripts/test_policy.py", line 154, in setUp<br/>    self._res = self.__class__.SharedResources(self.connections)<br/>  File "/contrail-test/tcutils/util.py", line 968, in __call__<br/>    Singleton, cls).__call__(*args, **kwargs)<br/>  File "/contrail-test/scripts/k8s_scripts/test_policy.py", line 22, in __init__<br/>    self.setUp()<br/>  File "/contrail-test/scripts/k8s_scripts/test_policy.py", line 109, in setUp<br/>    assert self.web_pod_ns1.verify_on_setup()<br/>AssertionError<br/>
<br/>
</code></td><td>323.668</td><td><a href="http://10.204.216.50/Docs/logs/2008-55_2020_08_17_13_45_33/logs//testnetworkpolicy.html#test_egress_rules_label_edit">
		    Log File
		  </a></td>
</tr>, <tr class="Error" valign="top">
<td>TestIngressClusterIp.test_ingress_ip_assignment[ci_k8s_sanity,k8s_sanity]</td><td>Failure</td><td><span onclick="javascript:toggleErrorDetail(this)" style="cursor:pointer">Details</span><code style="display:none">
<br/>
<br/>Traceback (most recent call last):<br/>testtools.testresult.real._StringException: Traceback (most recent call last):<br/>  File "/contrail-test/tcutils/wrappers.py", line 179, in wrapper<br/>    raise TestFailed("\n ".join(errmsg))<br/>tcutils.cores.TestFailed: Test failed: AssertionError<br/>Python 3.6.8: /usr/bin/python3<br/>Mon Aug 17 14:03:27 2020<br/>
<br/>A problem occurred in a Python script.  Here is the sequence of<br/>function calls leading up to the error, in the order they occurred.<br/>
<br/> /contrail-test/tcutils/wrappers.py in wrapper(self=&lt;scripts.k8s_scripts.test_ingress.TestIngressClu...ment[ci_k8s_sanity,k8s_sanity] id=0x7f2aec2e4cc0&gt;, *args=(), **kwargs={})<br/>   80             log.info('Initial checks done. Running the testcase now')<br/>   81             log.info('')<br/>   82             result = function(self, *args, **kwargs)<br/>   83             if self.inputs.upgrade:<br/>   84                 pid = os.getpid()<br/>result = None<br/>function = &lt;function TestIngressClusterIp.test_ingress_ip_assignment&gt;<br/>self = &lt;scripts.k8s_scripts.test_ingress.TestIngressClu...ment[ci_k8s_sanity,k8s_sanity] id=0x7f2aec2e4cc0&gt;<br/>args = ()<br/>kwargs = {}<br/>
<br/> /contrail-test/scripts/k8s_scripts/test_ingress.py in test_ingress_ip_assignment(self=&lt;scripts.k8s_scripts.test_ingress.TestIngressClu...ment[ci_k8s_sanity,k8s_sanity] id=0x7f2aec2e4cc0&gt;)<br/>   71         self.verify_nginx_pod(pod1)<br/>   72         self.verify_nginx_pod(pod2)<br/>   73         assert pod3.verify_on_setup()<br/>   74 <br/>   75         # Now validate ingress from within the cluster network<br/>pod3 = &lt;k8s.pod.PodFixture object&gt;<br/>pod3.verify_on_setup = &lt;bound method PodFixture.verify_on_setup of &lt;k8s.pod.PodFixture object&gt;&gt;<br/>AssertionError: <br/>    __cause__ = None<br/>    __class__ = &lt;class 'AssertionError'&gt;<br/>    __context__ = None<br/>    __delattr__ = &lt;method-wrapper '__delattr__' of AssertionError object&gt;<br/>    __dict__ = {}<br/>    __dir__ = &lt;built-in method __dir__ of AssertionError object&gt;<br/>    __doc__ = 'Assertion failed.'<br/>    __eq__ = &lt;method-wrapper '__eq__' of AssertionError object&gt;<br/>    __format__ = &lt;built-in method __format__ of AssertionError object&gt;<br/>    __ge__ = &lt;method-wrapper '__ge__' of AssertionError object&gt;<br/>    __getattribute__ = &lt;method-wrapper '__getattribute__' of AssertionError object&gt;<br/>    __gt__ = &lt;method-wrapper '__gt__' of AssertionError object&gt;<br/>    __hash__ = &lt;method-wrapper '__hash__' of AssertionError object&gt;<br/>    __init__ = &lt;method-wrapper '__init__' of AssertionError object&gt;<br/>    __init_subclass__ = &lt;built-in method __init_subclass__ of type object&gt;<br/>    __le__ = &lt;method-wrapper '__le__' of AssertionError object&gt;<br/>    __lt__ = &lt;method-wrapper '__lt__' of AssertionError object&gt;<br/>    __ne__ = &lt;method-wrapper '__ne__' of AssertionError object&gt;<br/>    __new__ = &lt;built-in method __new__ of type object&gt;<br/>    __reduce__ = &lt;built-in method __reduce__ of AssertionError object&gt;<br/>    __reduce_ex__ = &lt;built-in method __reduce_ex__ of AssertionError object&gt;<br/>    __repr__ = &lt;method-wrapper '__repr__' of AssertionError object&gt;<br/>    __setattr__ = &lt;method-wrapper '__setattr__' of AssertionError object&gt;<br/>    __setstate__ = &lt;built-in method __setstate__ of AssertionError object&gt;<br/>    __sizeof__ = &lt;built-in method __sizeof__ of AssertionError object&gt;<br/>    __str__ = &lt;method-wrapper '__str__' of AssertionError object&gt;<br/>    __subclasshook__ = &lt;built-in method __subclasshook__ of type object&gt;<br/>    __suppress_context__ = False<br/>    __traceback__ = &lt;traceback object&gt;<br/>    args = ()<br/>    with_traceback = &lt;built-in method with_traceback of AssertionError object&gt;<br/>
<br/>The above is a description of an error in a Python program.  Here is<br/>the original traceback:<br/>
<br/>Traceback (most recent call last):<br/>  File "/contrail-test/tcutils/wrappers.py", line 82, in wrapper<br/>    result = function(self, *args, **kwargs)<br/>  File "/contrail-test/scripts/k8s_scripts/test_ingress.py", line 73, in test_ingress_ip_assignment<br/>    assert pod3.verify_on_setup()<br/>AssertionError<br/>
<br/>
</code></td><td>918.551</td><td><a href="http://10.204.216.50/Docs/logs/2008-55_2020_08_17_13_45_33/logs//testingressclusterip.html#test_ingress_ip_assignment">
		    Log File
		  </a></td>
</tr>, <tr class="Error" valign="top">
<td>TestIngressTLS.test_ingress_tls_1[k8s_sanity]</td><td>Failure</td><td><span onclick="javascript:toggleErrorDetail(this)" style="cursor:pointer">Details</span><code style="display:none">
<br/>
<br/>Traceback (most recent call last):<br/>testtools.testresult.real._StringException: stdout: {{{[localhost] local: openssl req -x509 -nodes -days 365 -newkey rsa:2048 -keyout /tmp/key-bgdr95rk -out /tmp/cert-vvs6dj3m -subj "/CN=k8stest/O=k8stest"}}}<br/>
<br/>Traceback (most recent call last):<br/>  File "/contrail-test/tcutils/util.py", line 1129, in wrapper<br/>    return f(self, *func_args, **func_kwargs)<br/>  File "/contrail-test/tcutils/wrappers.py", line 179, in wrapper<br/>    raise TestFailed("\n ".join(errmsg))<br/>tcutils.cores.TestFailed: Test failed: AssertionError<br/>Python 3.6.8: /usr/bin/python3<br/>Mon Aug 17 14:03:21 2020<br/>
<br/>A problem occurred in a Python script.  Here is the sequence of<br/>function calls leading up to the error, in the order they occurred.<br/>
<br/> /contrail-test/tcutils/wrappers.py in wrapper(self=&lt;scripts.k8s_scripts.test_ingress_tls.TestIngres...test_ingress_tls_1[k8s_sanity] id=0x7fbbe1645438&gt;, *args=(), **kwargs={})<br/>   80             log.info('Initial checks done. Running the testcase now')<br/>   81             log.info('')<br/>   82             result = function(self, *args, **kwargs)<br/>   83             if self.inputs.upgrade:<br/>   84                 pid = os.getpid()<br/>result = None<br/>function = &lt;function TestIngressTLS.test_ingress_tls_1&gt;<br/>self = &lt;scripts.k8s_scripts.test_ingress_tls.TestIngres...test_ingress_tls_1[k8s_sanity] id=0x7fbbe1645438&gt;<br/>args = ()<br/>kwargs = {}<br/>
<br/> /contrail-test/scripts/k8s_scripts/test_ingress_tls.py in test_ingress_tls_1(self=&lt;scripts.k8s_scripts.test_ingress_tls.TestIngres...test_ingress_tls_1[k8s_sanity] id=0x7fbbe1645438&gt;)<br/>   49         self.verify_nginx_pod(pod1)<br/>   50         self.verify_nginx_pod(pod2)<br/>   51         assert pod3.verify_on_setup()<br/>   52 <br/>   53         # Now validate ingress from within the cluster network<br/>pod3 = &lt;k8s.pod.PodFixture object&gt;<br/>pod3.verify_on_setup = &lt;bound method PodFixture.verify_on_setup of &lt;k8s.pod.PodFixture object&gt;&gt;<br/>AssertionError: <br/>    __cause__ = None<br/>    __class__ = &lt;class 'AssertionError'&gt;<br/>    __context__ = None<br/>    __delattr__ = &lt;method-wrapper '__delattr__' of AssertionError object&gt;<br/>    __dict__ = {}<br/>    __dir__ = &lt;built-in method __dir__ of AssertionError object&gt;<br/>    __doc__ = 'Assertion failed.'<br/>    __eq__ = &lt;method-wrapper '__eq__' of AssertionError object&gt;<br/>    __format__ = &lt;built-in method __format__ of AssertionError object&gt;<br/>    __ge__ = &lt;method-wrapper '__ge__' of AssertionError object&gt;<br/>    __getattribute__ = &lt;method-wrapper '__getattribute__' of AssertionError object&gt;<br/>    __gt__ = &lt;method-wrapper '__gt__' of AssertionError object&gt;<br/>    __hash__ = &lt;method-wrapper '__hash__' of AssertionError object&gt;<br/>    __init__ = &lt;method-wrapper '__init__' of AssertionError object&gt;<br/>    __init_subclass__ = &lt;built-in method __init_subclass__ of type object&gt;<br/>    __le__ = &lt;method-wrapper '__le__' of AssertionError object&gt;<br/>    __lt__ = &lt;method-wrapper '__lt__' of AssertionError object&gt;<br/>    __ne__ = &lt;method-wrapper '__ne__' of AssertionError object&gt;<br/>    __new__ = &lt;built-in method __new__ of type object&gt;<br/>    __reduce__ = &lt;built-in method __reduce__ of AssertionError object&gt;<br/>    __reduce_ex__ = &lt;built-in method __reduce_ex__ of AssertionError object&gt;<br/>    __repr__ = &lt;method-wrapper '__repr__' of AssertionError object&gt;<br/>    __setattr__ = &lt;method-wrapper '__setattr__' of AssertionError object&gt;<br/>    __setstate__ = &lt;built-in method __setstate__ of AssertionError object&gt;<br/>    __sizeof__ = &lt;built-in method __sizeof__ of AssertionError object&gt;<br/>    __str__ = &lt;method-wrapper '__str__' of AssertionError object&gt;<br/>    __subclasshook__ = &lt;built-in method __subclasshook__ of type object&gt;<br/>    __suppress_context__ = False<br/>    __traceback__ = &lt;traceback object&gt;<br/>    args = ()<br/>    with_traceback = &lt;built-in method with_traceback of AssertionError object&gt;<br/>
<br/>The above is a description of an error in a Python program.  Here is<br/>the original traceback:<br/>
<br/>Traceback (most recent call last):<br/>  File "/contrail-test/tcutils/wrappers.py", line 82, in wrapper<br/>    result = function(self, *args, **kwargs)<br/>  File "/contrail-test/scripts/k8s_scripts/test_ingress_tls.py", line 51, in test_ingress_tls_1<br/>    assert pod3.verify_on_setup()<br/>AssertionError<br/>
<br/>
</code></td><td>923.285</td><td><a href="http://10.204.216.50/Docs/logs/2008-55_2020_08_17_13_45_33/logs//testingresstls.html#test_ingress_tls_1">
		    Log File
		  </a></td>
</tr>, <tr class="Error" valign="top">
<td>TestNetworkPolicy.test_ingress_rules_label_edit[k8s_sanity]</td><td>Failure</td><td><span onclick="javascript:toggleErrorDetail(this)" style="cursor:pointer">Details</span><code style="display:none">
<br/>
<br/>Traceback (most recent call last):<br/>testtools.testresult.real._StringException: Traceback (most recent call last):<br/>  File "/contrail-test/scripts/k8s_scripts/test_policy.py", line 154, in setUp<br/>    self._res = self.__class__.SharedResources(self.connections)<br/>  File "/contrail-test/tcutils/util.py", line 968, in __call__<br/>    Singleton, cls).__call__(*args, **kwargs)<br/>  File "/contrail-test/scripts/k8s_scripts/test_policy.py", line 22, in __init__<br/>    self.setUp()<br/>  File "/contrail-test/scripts/k8s_scripts/test_policy.py", line 109, in setUp<br/>    assert self.web_pod_ns1.verify_on_setup()<br/>AssertionError<br/>
<br/>
</code></td><td>323.032</td><td><a href="http://10.204.216.50/Docs/logs/2008-55_2020_08_17_13_45_33/logs//testnetworkpolicy.html#test_ingress_rules_label_edit">
		    Log File
		  </a></td>
</tr>, <tr class="Error" valign="top">
<td>.tearDownClass (scripts.k8s_scripts.test_policy.TestNetworkPolicy)</td><td>Failure</td><td><span onclick="javascript:toggleErrorDetail(this)" style="cursor:pointer">Details</span><code style="display:none">
<br/>
<br/>Traceback (most recent call last):<br/>testtools.testresult.real._StringException: Traceback (most recent call last):<br/>  File "/contrail-test/scripts/k8s_scripts/test_policy.py", line 172, in tearDownClass<br/>    if getattr(cls, '_shared_resources'):<br/>AttributeError: type object 'TestNetworkPolicy' has no attribute '_shared_resources'<br/>
<br/>
</code></td><td>0.000</td><td><a href="">
		    Log File
		  </a></td>
</tr>, <tr class="Error" valign="top">
<td>TestService.test_kube_dns_lookup[k8s_sanity]</td><td>Failure</td><td><span onclick="javascript:toggleErrorDetail(this)" style="cursor:pointer">Details</span><code style="display:none">
<br/>
<br/>Traceback (most recent call last):<br/>testtools.testresult.real._StringException: Traceback (most recent call last):<br/>  File "/contrail-test/tcutils/wrappers.py", line 179, in wrapper<br/>    raise TestFailed("\n ".join(errmsg))<br/>tcutils.cores.TestFailed: Test failed: AssertionError<br/>Python 3.6.8: /usr/bin/python3<br/>Mon Aug 17 14:08:38 2020<br/>
<br/>A problem occurred in a Python script.  Here is the sequence of<br/>function calls leading up to the error, in the order they occurred.<br/>
<br/> /contrail-test/tcutils/wrappers.py in wrapper(self=&lt;scripts.k8s_scripts.test_service.TestService.test_kube_dns_lookup[k8s_sanity] id=0x7fbbe1620cf8&gt;, *args=(), **kwargs={})<br/>   80             log.info('Initial checks done. Running the testcase now')<br/>   81             log.info('')<br/>   82             result = function(self, *args, **kwargs)<br/>   83             if self.inputs.upgrade:<br/>   84                 pid = os.getpid()<br/>result = None<br/>function = &lt;function TestService.test_kube_dns_lookup&gt;<br/>self = &lt;scripts.k8s_scripts.test_service.TestService.test_kube_dns_lookup[k8s_sanity] id=0x7fbbe1620cf8&gt;<br/>args = ()<br/>kwargs = {}<br/>
<br/> /contrail-test/scripts/k8s_scripts/test_service.py in test_kube_dns_lookup(self=&lt;scripts.k8s_scripts.test_service.TestService.test_kube_dns_lookup[k8s_sanity] id=0x7fbbe1620cf8&gt;)<br/>  238         namespace = self.setup_namespace()<br/>  239         client_pod = self.setup_busybox_pod(namespace=namespace.name)<br/>  240         assert client_pod.verify_on_setup()<br/>  241         lookup_str = 'nslookup kubernetes.default.svc.cluster.local'<br/>  242         output = client_pod.run_cmd(lookup_str)<br/>client_pod = &lt;k8s.pod.PodFixture object&gt;<br/>client_pod.verify_on_setup = &lt;bound method PodFixture.verify_on_setup of &lt;k8s.pod.PodFixture object&gt;&gt;<br/>AssertionError: <br/>    __cause__ = None<br/>    __class__ = &lt;class 'AssertionError'&gt;<br/>    __context__ = None<br/>    __delattr__ = &lt;method-wrapper '__delattr__' of AssertionError object&gt;<br/>    __dict__ = {}<br/>    __dir__ = &lt;built-in method __dir__ of AssertionError object&gt;<br/>    __doc__ = 'Assertion failed.'<br/>    __eq__ = &lt;method-wrapper '__eq__' of AssertionError object&gt;<br/>    __format__ = &lt;built-in method __format__ of AssertionError object&gt;<br/>    __ge__ = &lt;method-wrapper '__ge__' of AssertionError object&gt;<br/>    __getattribute__ = &lt;method-wrapper '__getattribute__' of AssertionError object&gt;<br/>    __gt__ = &lt;method-wrapper '__gt__' of AssertionError object&gt;<br/>    __hash__ = &lt;method-wrapper '__hash__' of AssertionError object&gt;<br/>    __init__ = &lt;method-wrapper '__init__' of AssertionError object&gt;<br/>    __init_subclass__ = &lt;built-in method __init_subclass__ of type object&gt;<br/>    __le__ = &lt;method-wrapper '__le__' of AssertionError object&gt;<br/>    __lt__ = &lt;method-wrapper '__lt__' of AssertionError object&gt;<br/>    __ne__ = &lt;method-wrapper '__ne__' of AssertionError object&gt;<br/>    __new__ = &lt;built-in method __new__ of type object&gt;<br/>    __reduce__ = &lt;built-in method __reduce__ of AssertionError object&gt;<br/>    __reduce_ex__ = &lt;built-in method __reduce_ex__ of AssertionError object&gt;<br/>    __repr__ = &lt;method-wrapper '__repr__' of AssertionError object&gt;<br/>    __setattr__ = &lt;method-wrapper '__setattr__' of AssertionError object&gt;<br/>    __setstate__ = &lt;built-in method __setstate__ of AssertionError object&gt;<br/>    __sizeof__ = &lt;built-in method __sizeof__ of AssertionError object&gt;<br/>    __str__ = &lt;method-wrapper '__str__' of AssertionError object&gt;<br/>    __subclasshook__ = &lt;built-in method __subclasshook__ of type object&gt;<br/>    __suppress_context__ = False<br/>    __traceback__ = &lt;traceback object&gt;<br/>    args = ()<br/>    with_traceback = &lt;built-in method with_traceback of AssertionError object&gt;<br/>
<br/>The above is a description of an error in a Python program.  Here is<br/>the original traceback:<br/>
<br/>Traceback (most recent call last):<br/>  File "/contrail-test/tcutils/wrappers.py", line 82, in wrapper<br/>    result = function(self, *args, **kwargs)<br/>  File "/contrail-test/scripts/k8s_scripts/test_service.py", line 240, in test_kube_dns_lookup<br/>    assert client_pod.verify_on_setup()<br/>AssertionError<br/>
<br/>
</code></td><td>307.653</td><td><a href="http://10.204.216.50/Docs/logs/2008-55_2020_08_17_13_45_33/logs//testservice.html#test_kube_dns_lookup">
		    Log File
		  </a></td>
</tr>, <tr class="Error" valign="top">
<td>TestServiceExternalIP.test_service_with_external_ip[k8s_sanity]</td><td>Failure</td><td><span onclick="javascript:toggleErrorDetail(this)" style="cursor:pointer">Details</span><code style="display:none">
<br/>
<br/>Traceback (most recent call last):<br/>testtools.testresult.real._StringException: Traceback (most recent call last):<br/>  File "/contrail-test/tcutils/util.py", line 1129, in wrapper<br/>    return f(self, *func_args, **func_kwargs)<br/>  File "/contrail-test/tcutils/wrappers.py", line 179, in wrapper<br/>    raise TestFailed("\n ".join(errmsg))<br/>tcutils.cores.TestFailed: Test failed: AssertionError<br/>Python 3.6.8: /usr/bin/python3<br/>Mon Aug 17 14:09:03 2020<br/>
<br/>A problem occurred in a Python script.  Here is the sequence of<br/>function calls leading up to the error, in the order they occurred.<br/>
<br/> /contrail-test/tcutils/wrappers.py in wrapper(self=&lt;scripts.k8s_scripts.test_service.TestServiceExt...e_with_external_ip[k8s_sanity] id=0x7f792bdfa128&gt;, *args=(), **kwargs={})<br/>   80             log.info('Initial checks done. Running the testcase now')<br/>   81             log.info('')<br/>   82             result = function(self, *args, **kwargs)<br/>   83             if self.inputs.upgrade:<br/>   84                 pid = os.getpid()<br/>result = None<br/>function = &lt;function TestServiceExternalIP.test_service_with_external_ip&gt;<br/>self = &lt;scripts.k8s_scripts.test_service.TestServiceExt...e_with_external_ip[k8s_sanity] id=0x7f792bdfa128&gt;<br/>args = ()<br/>kwargs = {}<br/>
<br/> /contrail-test/scripts/k8s_scripts/test_service.py in test_service_with_external_ip(self=&lt;scripts.k8s_scripts.test_service.TestServiceExt...e_with_external_ip[k8s_sanity] id=0x7f792bdfa128&gt;)<br/>  344         pod3 = self.setup_busybox_pod(namespace=namespace.name)<br/>  345 <br/>  346         assert self.verify_nginx_pod(pod1)<br/>  347         assert self.verify_nginx_pod(pod2)<br/>  348         assert pod3.verify_on_setup()<br/>self = &lt;scripts.k8s_scripts.test_service.TestServiceExt...e_with_external_ip[k8s_sanity] id=0x7f792bdfa128&gt;<br/>self.verify_nginx_pod = &lt;bound method BaseK8sTest.verify_nginx_pod of &lt;s..._with_external_ip[k8s_sanity] id=0x7f792bdfa128&gt;&gt;<br/>pod1 = &lt;k8s.pod.PodFixture object&gt;<br/>AssertionError: <br/>    __cause__ = None<br/>    __class__ = &lt;class 'AssertionError'&gt;<br/>    __context__ = None<br/>    __delattr__ = &lt;method-wrapper '__delattr__' of AssertionError object&gt;<br/>    __dict__ = {}<br/>    __dir__ = &lt;built-in method __dir__ of AssertionError object&gt;<br/>    __doc__ = 'Assertion failed.'<br/>    __eq__ = &lt;method-wrapper '__eq__' of AssertionError object&gt;<br/>    __format__ = &lt;built-in method __format__ of AssertionError object&gt;<br/>    __ge__ = &lt;method-wrapper '__ge__' of AssertionError object&gt;<br/>    __getattribute__ = &lt;method-wrapper '__getattribute__' of AssertionError object&gt;<br/>    __gt__ = &lt;method-wrapper '__gt__' of AssertionError object&gt;<br/>    __hash__ = &lt;method-wrapper '__hash__' of AssertionError object&gt;<br/>    __init__ = &lt;method-wrapper '__init__' of AssertionError object&gt;<br/>    __init_subclass__ = &lt;built-in method __init_subclass__ of type object&gt;<br/>    __le__ = &lt;method-wrapper '__le__' of AssertionError object&gt;<br/>    __lt__ = &lt;method-wrapper '__lt__' of AssertionError object&gt;<br/>    __ne__ = &lt;method-wrapper '__ne__' of AssertionError object&gt;<br/>    __new__ = &lt;built-in method __new__ of type object&gt;<br/>    __reduce__ = &lt;built-in method __reduce__ of AssertionError object&gt;<br/>    __reduce_ex__ = &lt;built-in method __reduce_ex__ of AssertionError object&gt;<br/>    __repr__ = &lt;method-wrapper '__repr__' of AssertionError object&gt;<br/>    __setattr__ = &lt;method-wrapper '__setattr__' of AssertionError object&gt;<br/>    __setstate__ = &lt;built-in method __setstate__ of AssertionError object&gt;<br/>    __sizeof__ = &lt;built-in method __sizeof__ of AssertionError object&gt;<br/>    __str__ = &lt;method-wrapper '__str__' of AssertionError object&gt;<br/>    __subclasshook__ = &lt;built-in method __subclasshook__ of type object&gt;<br/>    __suppress_context__ = False<br/>    __traceback__ = &lt;traceback object&gt;<br/>    args = ()<br/>    with_traceback = &lt;built-in method with_traceback of AssertionError object&gt;<br/>
<br/>The above is a description of an error in a Python program.  Here is<br/>the original traceback:<br/>
<br/>Traceback (most recent call last):<br/>  File "/contrail-test/tcutils/wrappers.py", line 82, in wrapper<br/>    result = function(self, *args, **kwargs)<br/>  File "/contrail-test/scripts/k8s_scripts/test_service.py", line 346, in test_service_with_external_ip<br/>    assert self.verify_nginx_pod(pod1)<br/>AssertionError<br/>
<br/>
</code></td><td>308.596</td><td><a href="http://10.204.216.50/Docs/logs/2008-55_2020_08_17_13_45_33/logs//testserviceexternalip.html#test_service_with_external_ip">
		    Log File
		  </a></td>
</tr>, <tr class="Error" valign="top">
<td>TestNetworkPolicyServiceIngress.test_egress_rule_on_namespace_with_service[k8s_sanity]</td><td>Failure</td><td><span onclick="javascript:toggleErrorDetail(this)" style="cursor:pointer">Details</span><code style="display:none">
<br/>
<br/>Traceback (most recent call last):<br/>testtools.testresult.real._StringException: Traceback (most recent call last):<br/>  File "/contrail-test/scripts/k8s_scripts/test_policy.py", line 2899, in setUp<br/>    self._res = self.__class__.SharedResources(self.connections)<br/>  File "/contrail-test/tcutils/util.py", line 968, in __call__<br/>    Singleton, cls).__call__(*args, **kwargs)<br/>  File "/contrail-test/scripts/k8s_scripts/test_policy.py", line 2777, in __init__<br/>    self.setUp()<br/>  File "/contrail-test/scripts/k8s_scripts/test_policy.py", line 2857, in setUp<br/>    assert self.web1_pod_ns1.verify_on_setup()<br/>AssertionError<br/>
<br/>
</code></td><td>349.539</td><td><a href="http://10.204.216.50/Docs/logs/2008-55_2020_08_17_13_45_33/logs//testnetworkpolicyserviceingress.html#test_egress_rule_on_namespace_with_service">
		    Log File
		  </a></td>
</tr>, <tr class="Error" valign="top">
<td>TestSNAT.test_deployment_with_replica_update_for_snat[k8s_sanity]</td><td>Failure</td><td><span onclick="javascript:toggleErrorDetail(this)" style="cursor:pointer">Details</span><code style="display:none">
<br/>
<br/>Traceback (most recent call last):<br/>testtools.testresult.real._StringException: Traceback (most recent call last):<br/>  File "/contrail-test/tcutils/wrappers.py", line 179, in wrapper<br/>    raise TestFailed("\n ".join(errmsg))<br/>tcutils.cores.TestFailed: Test failed: AssertionError<br/>Python 3.6.8: /usr/bin/python3<br/>Mon Aug 17 14:13:46 2020<br/>
<br/>A problem occurred in a Python script.  Here is the sequence of<br/>function calls leading up to the error, in the order they occurred.<br/>
<br/> /contrail-test/tcutils/wrappers.py in wrapper(self=&lt;scripts.k8s_scripts.test_snat.TestSNAT.test_dep...ca_update_for_snat[k8s_sanity] id=0x7fbbe162eb70&gt;, *args=(), **kwargs={})<br/>   80             log.info('Initial checks done. Running the testcase now')<br/>   81             log.info('')<br/>   82             result = function(self, *args, **kwargs)<br/>   83             if self.inputs.upgrade:<br/>   84                 pid = os.getpid()<br/>result = None<br/>function = &lt;function TestSNAT.test_deployment_with_replica_update_for_snat&gt;<br/>self = &lt;scripts.k8s_scripts.test_snat.TestSNAT.test_dep...ca_update_for_snat[k8s_sanity] id=0x7fbbe162eb70&gt;<br/>args = ()<br/>kwargs = {}<br/>
<br/> /contrail-test/scripts/k8s_scripts/test_snat.py in test_deployment_with_replica_update_for_snat(self=&lt;scripts.k8s_scripts.test_snat.TestSNAT.test_dep...ca_update_for_snat[k8s_sanity] id=0x7fbbe162eb70&gt;)<br/>  224         dep_1 =  self.setup_deployment(name=name, namespace=namespace1_name,<br/>  225                                      metadata=metadata, spec=spec)<br/>  226         assert dep_1.verify_on_setup()<br/>  227         s_pod_fixtures = []<br/>  228         server_pods = dep_1.get_pods_list()<br/>dep_1 = &lt;k8s.deployment.DeploymentFixture object&gt;<br/>dep_1.verify_on_setup = &lt;bound method DeploymentFixture.verify_on_setup of &lt;k8s.deployment.DeploymentFixture object&gt;&gt;<br/>AssertionError: <br/>    __cause__ = None<br/>    __class__ = &lt;class 'AssertionError'&gt;<br/>    __context__ = None<br/>    __delattr__ = &lt;method-wrapper '__delattr__' of AssertionError object&gt;<br/>    __dict__ = {}<br/>    __dir__ = &lt;built-in method __dir__ of AssertionError object&gt;<br/>    __doc__ = 'Assertion failed.'<br/>    __eq__ = &lt;method-wrapper '__eq__' of AssertionError object&gt;<br/>    __format__ = &lt;built-in method __format__ of AssertionError object&gt;<br/>    __ge__ = &lt;method-wrapper '__ge__' of AssertionError object&gt;<br/>    __getattribute__ = &lt;method-wrapper '__getattribute__' of AssertionError object&gt;<br/>    __gt__ = &lt;method-wrapper '__gt__' of AssertionError object&gt;<br/>    __hash__ = &lt;method-wrapper '__hash__' of AssertionError object&gt;<br/>    __init__ = &lt;method-wrapper '__init__' of AssertionError object&gt;<br/>    __init_subclass__ = &lt;built-in method __init_subclass__ of type object&gt;<br/>    __le__ = &lt;method-wrapper '__le__' of AssertionError object&gt;<br/>    __lt__ = &lt;method-wrapper '__lt__' of AssertionError object&gt;<br/>    __ne__ = &lt;method-wrapper '__ne__' of AssertionError object&gt;<br/>    __new__ = &lt;built-in method __new__ of type object&gt;<br/>    __reduce__ = &lt;built-in method __reduce__ of AssertionError object&gt;<br/>    __reduce_ex__ = &lt;built-in method __reduce_ex__ of AssertionError object&gt;<br/>    __repr__ = &lt;method-wrapper '__repr__' of AssertionError object&gt;<br/>    __setattr__ = &lt;method-wrapper '__setattr__' of AssertionError object&gt;<br/>    __setstate__ = &lt;built-in method __setstate__ of AssertionError object&gt;<br/>    __sizeof__ = &lt;built-in method __sizeof__ of AssertionError object&gt;<br/>    __str__ = &lt;method-wrapper '__str__' of AssertionError object&gt;<br/>    __subclasshook__ = &lt;built-in method __subclasshook__ of type object&gt;<br/>    __suppress_context__ = False<br/>    __traceback__ = &lt;traceback object&gt;<br/>    args = ()<br/>    with_traceback = &lt;built-in method with_traceback of AssertionError object&gt;<br/>
<br/>The above is a description of an error in a Python program.  Here is<br/>the original traceback:<br/>
<br/>Traceback (most recent call last):<br/>  File "/contrail-test/tcutils/wrappers.py", line 82, in wrapper<br/>    result = function(self, *args, **kwargs)<br/>  File "/contrail-test/scripts/k8s_scripts/test_snat.py", line 226, in test_deployment_with_replica_update_for_snat<br/>    assert dep_1.verify_on_setup()<br/>AssertionError<br/>
<br/>
</code></td><td>317.122</td><td><a href="http://10.204.216.50/Docs/logs/2008-55_2020_08_17_13_45_33/logs//testsnat.html#test_deployment_with_replica_update_for_snat">
		    Log File
		  </a></td>
</tr>, <tr class="Error" valign="top">
<td>TestNetworkPolicyServiceIngress.test_ingress_rule_on_namespace_with_k8s_ingress_fanout[k8s_sanity]</td><td>Failure</td><td><span onclick="javascript:toggleErrorDetail(this)" style="cursor:pointer">Details</span><code style="display:none">
<br/>
<br/>Traceback (most recent call last):<br/>testtools.testresult.real._StringException: Traceback (most recent call last):<br/>  File "/contrail-test/scripts/k8s_scripts/test_policy.py", line 2899, in setUp<br/>    self._res = self.__class__.SharedResources(self.connections)<br/>  File "/contrail-test/tcutils/util.py", line 968, in __call__<br/>    Singleton, cls).__call__(*args, **kwargs)<br/>  File "/contrail-test/scripts/k8s_scripts/test_policy.py", line 2777, in __init__<br/>    self.setUp()<br/>  File "/contrail-test/scripts/k8s_scripts/test_policy.py", line 2857, in setUp<br/>    assert self.web1_pod_ns1.verify_on_setup()<br/>AssertionError<br/>
<br/>
</code></td><td>323.217</td><td><a href="http://10.204.216.50/Docs/logs/2008-55_2020_08_17_13_45_33/logs//testnetworkpolicyserviceingress.html#test_ingress_rule_on_namespace_with_k8s_ingress_fanout">
		    Log File
		  </a></td>
</tr>, <tr class="Error" valign="top">
<td>TestNetworkPolicyServiceIngress.test_ingress_rule_on_namespace_with_service[k8s_sanity]</td><td>Failure</td><td><span onclick="javascript:toggleErrorDetail(this)" style="cursor:pointer">Details</span><code style="display:none">
<br/>
<br/>Traceback (most recent call last):<br/>testtools.testresult.real._StringException: Traceback (most recent call last):<br/>  File "/contrail-test/scripts/k8s_scripts/test_policy.py", line 2899, in setUp<br/>    self._res = self.__class__.SharedResources(self.connections)<br/>  File "/contrail-test/tcutils/util.py", line 968, in __call__<br/>    Singleton, cls).__call__(*args, **kwargs)<br/>  File "/contrail-test/scripts/k8s_scripts/test_policy.py", line 2777, in __init__<br/>    self.setUp()<br/>  File "/contrail-test/scripts/k8s_scripts/test_policy.py", line 2857, in setUp<br/>    assert self.web1_pod_ns1.verify_on_setup()<br/>AssertionError<br/>
<br/>
</code></td><td>357.071</td><td><a href="http://10.204.216.50/Docs/logs/2008-55_2020_08_17_13_45_33/logs//testnetworkpolicyserviceingress.html#test_ingress_rule_on_namespace_with_service">
		    Log File
		  </a></td>
</tr>, <tr class="Error" valign="top">
<td>TestNetworkPolicyRandom.test_deployment_replica_updation[k8s_sanity]</td><td>Failure</td><td><span onclick="javascript:toggleErrorDetail(this)" style="cursor:pointer">Details</span><code style="display:none">
<br/>
<br/>Traceback (most recent call last):<br/>testtools.testresult.real._StringException: Traceback (most recent call last):<br/>  File "/contrail-test/tcutils/wrappers.py", line 179, in wrapper<br/>    raise TestFailed("\n ".join(errmsg))<br/>tcutils.cores.TestFailed: Test failed: AttributeError<br/>Python 3.6.8: /usr/bin/python3<br/>Mon Aug 17 14:21:08 2020<br/>
<br/>A problem occurred in a Python script.  Here is the sequence of<br/>function calls leading up to the error, in the order they occurred.<br/>
<br/> /contrail-test/tcutils/wrappers.py in wrapper(self=&lt;scripts.k8s_scripts.test_policy.TestNetworkPoli...t_replica_updation[k8s_sanity] id=0x7f38bd49f860&gt;, *args=(), **kwargs={})<br/>   80             log.info('Initial checks done. Running the testcase now')<br/>   81             log.info('')<br/>   82             result = function(self, *args, **kwargs)<br/>   83             if self.inputs.upgrade:<br/>   84                 pid = os.getpid()<br/>result = None<br/>function = &lt;function TestNetworkPolicyRandom.test_deployment_replica_updation&gt;<br/>self = &lt;scripts.k8s_scripts.test_policy.TestNetworkPoli...t_replica_updation[k8s_sanity] id=0x7f38bd49f860&gt;<br/>args = ()<br/>kwargs = {}<br/>
<br/> /contrail-test/scripts/k8s_scripts/test_policy.py in test_deployment_replica_updation(self=&lt;scripts.k8s_scripts.test_policy.TestNetworkPoli...t_replica_updation[k8s_sanity] id=0x7f38bd49f860&gt;)<br/> 2407 <br/> 2408         assert deployment.verify_on_setup()<br/> 2409         ingress_allow_cidr = client1_pod_ns2.pod_ip + "/32"<br/> 2410         policy_types = ["Ingress"]<br/> 2411         ingress_list = [<br/>ingress_allow_cidr undefined<br/>client1_pod_ns2 = &lt;k8s.pod.PodFixture object&gt;<br/>client1_pod_ns2.pod_ip undefined<br/>AttributeError: 'PodFixture' object has no attribute 'pod_ip'<br/>    __cause__ = None<br/>    __class__ = &lt;class 'AttributeError'&gt;<br/>    __context__ = None<br/>    __delattr__ = &lt;method-wrapper '__delattr__' of AttributeError object&gt;<br/>    __dict__ = {}<br/>    __dir__ = &lt;built-in method __dir__ of AttributeError object&gt;<br/>    __doc__ = 'Attribute not found.'<br/>    __eq__ = &lt;method-wrapper '__eq__' of AttributeError object&gt;<br/>    __format__ = &lt;built-in method __format__ of AttributeError object&gt;<br/>    __ge__ = &lt;method-wrapper '__ge__' of AttributeError object&gt;<br/>    __getattribute__ = &lt;method-wrapper '__getattribute__' of AttributeError object&gt;<br/>    __gt__ = &lt;method-wrapper '__gt__' of AttributeError object&gt;<br/>    __hash__ = &lt;method-wrapper '__hash__' of AttributeError object&gt;<br/>    __init__ = &lt;method-wrapper '__init__' of AttributeError object&gt;<br/>    __init_subclass__ = &lt;built-in method __init_subclass__ of type object&gt;<br/>    __le__ = &lt;method-wrapper '__le__' of AttributeError object&gt;<br/>    __lt__ = &lt;method-wrapper '__lt__' of AttributeError object&gt;<br/>    __ne__ = &lt;method-wrapper '__ne__' of AttributeError object&gt;<br/>    __new__ = &lt;built-in method __new__ of type object&gt;<br/>    __reduce__ = &lt;built-in method __reduce__ of AttributeError object&gt;<br/>    __reduce_ex__ = &lt;built-in method __reduce_ex__ of AttributeError object&gt;<br/>    __repr__ = &lt;method-wrapper '__repr__' of AttributeError object&gt;<br/>    __setattr__ = &lt;method-wrapper '__setattr__' of AttributeError object&gt;<br/>    __setstate__ = &lt;built-in method __setstate__ of AttributeError object&gt;<br/>    __sizeof__ = &lt;built-in method __sizeof__ of AttributeError object&gt;<br/>    __str__ = &lt;method-wrapper '__str__' of AttributeError object&gt;<br/>    __subclasshook__ = &lt;built-in method __subclasshook__ of type object&gt;<br/>    __suppress_context__ = False<br/>    __traceback__ = &lt;traceback object&gt;<br/>    args = ("'PodFixture' object has no attribute 'pod_ip'",)<br/>    with_traceback = &lt;built-in method with_traceback of AttributeError object&gt;<br/>
<br/>The above is a description of an error in a Python program.  Here is<br/>the original traceback:<br/>
<br/>Traceback (most recent call last):<br/>  File "/contrail-test/tcutils/wrappers.py", line 82, in wrapper<br/>    result = function(self, *args, **kwargs)<br/>  File "/contrail-test/scripts/k8s_scripts/test_policy.py", line 2409, in test_deployment_replica_updation<br/>    ingress_allow_cidr = client1_pod_ns2.pod_ip + "/32"<br/>AttributeError: 'PodFixture' object has no attribute 'pod_ip'<br/>
<br/>
</code></td><td>1752.804</td><td><a href="http://10.204.216.50/Docs/logs/2008-55_2020_08_17_13_45_33/logs//testnetworkpolicyrandom.html#test_deployment_replica_updation">
		    Log File
		  </a></td>
</tr>, <tr class="Error" valign="top">
<td>TestNetworkPolicyRestart.test_policy_kubelet_restart_on_slave[k8s_sanity]</td><td>Failure</td><td><span onclick="javascript:toggleErrorDetail(this)" style="cursor:pointer">Details</span><code style="display:none">
<br/>
<br/>Traceback (most recent call last):<br/>testtools.testresult.real._StringException: Traceback (most recent call last):<br/>  File "/contrail-test/tcutils/util.py", line 1129, in wrapper<br/>    return f(self, *func_args, **func_kwargs)<br/>  File "/contrail-test/tcutils/wrappers.py", line 179, in wrapper<br/>    raise TestFailed("\n ".join(errmsg))<br/>tcutils.cores.TestFailed: Test failed: AssertionError<br/>Python 3.6.8: /usr/bin/python3<br/>Mon Aug 17 16:21:35 2020<br/>
<br/>A problem occurred in a Python script.  Here is the sequence of<br/>function calls leading up to the error, in the order they occurred.<br/>
<br/> /contrail-test/tcutils/wrappers.py in wrapper(self=&lt;serial_scripts.k8s_scripts.test_policy.TestNetw...t_restart_on_slave[k8s_sanity] id=0x7fa1b33f5828&gt;, *args=(), **kwargs={})<br/>   80             log.info('Initial checks done. Running the testcase now')<br/>   81             log.info('')<br/>   82             result = function(self, *args, **kwargs)<br/>   83             if self.inputs.upgrade:<br/>   84                 pid = os.getpid()<br/>result = None<br/>function = &lt;function TestNetworkPolicyRestart.test_policy_kubelet_restart_on_slave&gt;<br/>self = &lt;serial_scripts.k8s_scripts.test_policy.TestNetw...t_restart_on_slave[k8s_sanity] id=0x7fa1b33f5828&gt;<br/>args = ()<br/>kwargs = {}<br/>
<br/> /contrail-test/serial_scripts/k8s_scripts/test_policy.py in test_policy_kubelet_restart_on_slave(self=&lt;serial_scripts.k8s_scripts.test_policy.TestNetw...t_restart_on_slave[k8s_sanity] id=0x7fa1b33f5828&gt;)<br/>  687         # Restart POD used as PodSelector in the rule<br/>  688         self.inputs.restart_service(service_name = "kubelet",<br/>  689                                             host_ips = self.inputs.k8s_slave_ips)<br/>  690         time.sleep(30) # Wait timer for all kubernetes pods to stablise.<br/>  691         # Verify that policy works fine after restart<br/>host_ips undefined<br/>self = &lt;serial_scripts.k8s_scripts.test_policy.TestNetw...t_restart_on_slave[k8s_sanity] id=0x7fa1b33f5828&gt;<br/>self.inputs = &lt;common.contrail_test_init.ContrailTestInit object&gt;<br/>self.inputs.k8s_slave_ips = ['10.204.218.104', '10.204.218.105']<br/>
<br/> /contrail-test/common/contrail_test_init.py in restart_service(self=&lt;common.contrail_test_init.ContrailTestInit object&gt;, service_name='kubelet', host_ips=['10.204.218.104', '10.204.218.105'], container=None, verify_service=True)<br/> 1428                         container=None, verify_service=True):<br/> 1429         self._action_on_service(service_name, 'restart', host_ips, container,<br/> 1430             verify_service=verify_service)<br/> 1431     # end restart_service<br/> 1432 <br/>verify_service = True<br/>
<br/> /contrail-test/common/contrail_test_init.py in _action_on_service(self=&lt;common.contrail_test_init.ContrailTestInit object&gt;, service_name='kubelet', event='restart', host_ips=['10.204.218.104', '10.204.218.105'], container=None, verify_service=True)<br/> 1422                 if verify_service and (event == 'restart'):<br/> 1423                     assert self.verify_service_state(host, service=service_name)[0] ,\<br/> 1424                                "Service Restart failed for %s" % (service_name)<br/> 1425     #end _action_on_service<br/> 1426 <br/>service_name = 'kubelet'<br/>AssertionError: Service Restart failed for kubelet<br/>    __cause__ = None<br/>    __class__ = &lt;class 'AssertionError'&gt;<br/>    __context__ = None<br/>    __delattr__ = &lt;method-wrapper '__delattr__' of AssertionError object&gt;<br/>    __dict__ = {}<br/>    __dir__ = &lt;built-in method __dir__ of AssertionError object&gt;<br/>    __doc__ = 'Assertion failed.'<br/>    __eq__ = &lt;method-wrapper '__eq__' of AssertionError object&gt;<br/>    __format__ = &lt;built-in method __format__ of AssertionError object&gt;<br/>    __ge__ = &lt;method-wrapper '__ge__' of AssertionError object&gt;<br/>    __getattribute__ = &lt;method-wrapper '__getattribute__' of AssertionError object&gt;<br/>    __gt__ = &lt;method-wrapper '__gt__' of AssertionError object&gt;<br/>    __hash__ = &lt;method-wrapper '__hash__' of AssertionError object&gt;<br/>    __init__ = &lt;method-wrapper '__init__' of AssertionError object&gt;<br/>    __init_subclass__ = &lt;built-in method __init_subclass__ of type object&gt;<br/>    __le__ = &lt;method-wrapper '__le__' of AssertionError object&gt;<br/>    __lt__ = &lt;method-wrapper '__lt__' of AssertionError object&gt;<br/>    __ne__ = &lt;method-wrapper '__ne__' of AssertionError object&gt;<br/>    __new__ = &lt;built-in method __new__ of type object&gt;<br/>    __reduce__ = &lt;built-in method __reduce__ of AssertionError object&gt;<br/>    __reduce_ex__ = &lt;built-in method __reduce_ex__ of AssertionError object&gt;<br/>    __repr__ = &lt;method-wrapper '__repr__' of AssertionError object&gt;<br/>    __setattr__ = &lt;method-wrapper '__setattr__' of AssertionError object&gt;<br/>    __setstate__ = &lt;built-in method __setstate__ of AssertionError object&gt;<br/>    __sizeof__ = &lt;built-in method __sizeof__ of AssertionError object&gt;<br/>    __str__ = &lt;method-wrapper '__str__' of AssertionError object&gt;<br/>    __subclasshook__ = &lt;built-in method __subclasshook__ of type object&gt;<br/>    __suppress_context__ = False<br/>    __traceback__ = &lt;traceback object&gt;<br/>    args = ('Service Restart failed for kubelet',)<br/>    with_traceback = &lt;built-in method with_traceback of AssertionError object&gt;<br/>
<br/>The above is a description of an error in a Python program.  Here is<br/>the original traceback:<br/>
<br/>Traceback (most recent call last):<br/>  File "/contrail-test/tcutils/wrappers.py", line 82, in wrapper<br/>    result = function(self, *args, **kwargs)<br/>  File "/contrail-test/serial_scripts/k8s_scripts/test_policy.py", line 689, in test_policy_kubelet_restart_on_slave<br/>    host_ips = self.inputs.k8s_slave_ips)<br/>  File "/contrail-test/common/contrail_test_init.py", line 1430, in restart_service<br/>    verify_service=verify_service)<br/>  File "/contrail-test/common/contrail_test_init.py", line 1424, in _action_on_service<br/>    "Service Restart failed for %s" % (service_name)<br/>AssertionError: Service Restart failed for kubelet<br/>
<br/>
</code></td><td>55.928</td><td><a href="http://10.204.216.50/Docs/logs/2008-55_2020_08_17_13_45_33/logs//testnetworkpolicyrestart.html#test_policy_kubelet_restart_on_slave">
		    Log File
		  </a></td>
</tr>]